Workbook

Sheet 📋 Collecte Entretiens
A1: CARTOGRAPHIE DES OUTILS IT – CHANTIER BOUYGUES CONSTRUCTION
A3: N° | B3: Date Entretien | C3: Service / Département | D3: Interlocuteur | E3: FLUX | F3: Nature | G3: Nom de l'Outil | H3: Usage / Pourquoi | I3: Interne / Externe | J3: Éditeur / Fournisseur | K3: Alimentation (Manuel/Auto) | L3: Fréquence d'utilisation | M3: Alimenté par qui | N3: Alimente quel outil | O3: Interfaces / Connexions | P3: Niveau Maturité | Q3: Commentaires / Points d'attention | R3: Colonne32
A4: =ROW()-3 -> 1 | B4: 46169 | C4: Direction | D4: Julie | E4: GESTION DES ST | F4: Socle de données | G4: BATIS | H4: Declaration des ST(paiement direct) | I4: Externe | J4: Tisseo | K4: Manuel | L4: Quotidien | M4: Alimenté par Julie, les sous traitants, tisseo, m.o, attestation légal (connecté en temps réel) | N4: Aucun | O4: 4 – Optimisé | P4: Assez mature maintenant | Q4: NA
A5: =ROW()-3 -> 2 | B5: 46169 | C5: Direction | D5: Julie | E5: CIRCUIT DE VALIDATION | F5: Application métiers | G5: E-paraph | H5: Circuit de validation en interne avant signature | I5: Interne | J5: E-paraph | K5: Manuel | L5: Quotidien | M5: Tout le monde | N5: Aucun | O5: 3 – Mature | P5: Mature | Q5: Manque d'ergonomie sur le tab de co (quel ST concerné + Numéro contrat) | R5: Application métiers | W5: Application métiers
A6: =ROW()-3 -> 3 | B6: 46169 | C6: Direction | D6: Julie | E6: CIRCUIT DE VALIDATION | F6: Application métiers | G6: Docusign | I6: Externe | J6: Docusign | K6: Manuel | L6: Quotidien | N6: Aucun | O6: 3 – Mature | P6: Mature | W6: Socle de données
A7: =ROW()-3 -> 4 | B7: 46169 | C7: Direction | D7: Julie | E7: N.A | F7: Application métiers | G7: CWT | H7: Plateforme de voyage adapté à la politique voyage de Bouygues | I7: Externe | J7: CWT EUROPE | K7: Manuel | L7: Hebdomadaire | M7: Julie alimente au niveau de la resa, après il y a un circuit de validation(envoyé à un supérieur hiérarchique)=> politique voyage | N7: Relier à un autre logica bouyguesiel de compt | O7: 3 – Mature | P7: Mature | W7: Application métiers/Socle de donnée
A8: =ROW()-3 -> 5 | B8: 46169 | C8: Direction | D8: Julie | E8: N.A | F8: Application métiers | G8: Tableau | H8: Commande traiteur | I8: Externe | J8: Microsoft | K8: Manuel | L8: Ponctuel | N8: Aucun | O8: 3 – Mature | P8: Mature
A9: =ROW()-3 -> 6 | B9: 46169 | C9: Direction | D9: Julie | E9: GESTION DES MATÉRIELS | F9: Application métiers | G9: Oasis | H9: Déclaration d'incidents | I9: Interne | J9: Microsoft | K9: Manuel | L9: Ponctuel | M9: Tout le monde (Bouygues) | N9: Aucun | O9: 3 – Mature | P9: Mature
A10: =ROW()-3 -> 7 | B10: 46169 | C10: Direction | D10: Julie | E10: GESTION DES CONTRATS | F10: Application métiers | G10: Excel | H10: Contrats avenant, ordre de service, courrier | I10: Externe | J10: Microsoft | K10: Manuel | N10: Sharepoint | O10: 3 – Mature | P10: Mature
A11: =ROW()-3 -> 8 | B11: 46169 | C11: Direction | D11: Julie | E11: N.A | F11: Application métiers | G11: Word | H11: Courrier | I11: Externe | J11: Microsoft | K11: Manuel | L11: Ponctuel | N11: Aucun | O11: 3 – Mature | P11: Mature
A12: =ROW()-3 -> 9 | B12: 46169 | C12: Direction | D12: Julie | E12: GESTION DES ST | F12: Application métiers | G12: E-checking | H12: Pour les entreprises, Julie créer l'acces de l'entreprise(ST, prestataire ) | I12: Externe | J12: BYCN | K12: Manuel | L12: Ponctuel | M12: Julie, Valérie | N12: Aucun | O12: 1 – Basique | P12: Mature
A13: =ROW()-3 -> 10 | B13: 46170 | C13: Qualité | D13: Alexandre | E13: Contrôle Qualité | F13: Socle de données | G13: Quickconnect | H13: Workflow de contrôle qualité bétonnage, eprouvettes, accueil sécurité, formation post travail | I13: Interne | J13: Synologie | K13: Manuel | L13: Quotidien | M13: Tout le monde(travaux, prestatire, sous traitants, | N13: Sharepoint | O13: Connexion avec les mails et le sharepoint doe(dossier d'ouvrages éxécuté), prestataires externes (Sgma Beton) => pas fluide | P13: Pas mature => plein de bug, niveau connexion ok, | Q13: Constistution du Doe => via le workflow => fiche de contrôle(defintion des points d'arrets, plan de contrôle , deversement sur le sharepoint, verification par les conducteurs de travaux)
A14: =ROW()-3 -> 11 | B14: 46170 | C14: Qualité | D14: Alexandre | E14: Commande de matériel | F14: Socle de données | G14: Pablo | H14: Acheter du matériel | I14: Interne | J14: Systra | K14: Manuel | L14: Mensuel | M14: Tout le monde(travaux, prestatire, sous traitants, | N14: HARMONIE | O14: Mature
A15: =ROW()-3 -> 12 | B15: 46170 | C15: Qualité | D15: Alexandre | E15: Contrôle Qualité (visualisation) | F15: Application métiers | G15: Cabine de pilotage(Power BI) | H15: Pas utilisé | I15: Interne | J15: BYCN | K15: Automatique | L15: Ponctuel | N15: Aucun | O15: BYCN(sharepoint) | Q15: Outils sous exploité => indicateur de suivi
A16: =ROW()-3 -> 13 | B16: 46170 | C16: Qualité | D16: Alexandre | E16: Contrôle Qualité | F16: Application métiers | G16: Excel | H16: TCD | I16: Externe | J16: Microsoft | K16: Manuel | L16: Regulierement | M16: Alexandre | N16: Aucun
A17: =ROW()-3 -> 14 | B17: 46170 | C17: Qualité | D17: Alexandre | E17: MAD | F17: Application métiers | G17: IDCAPTURE | H17: Lever de reserve(mis à disposition pour les prochain prestataire, code couleur, visuel plus parlant , suivi dans le temps, position dans l'espace ) | I17: Externe | J17: IDCAPTURE | K17: Manuel | L17: Quotidien | M17: Equipe travaux, Qualité, MOE | N17: Aucun | O17: Alexandre admin, met en place les comptes utilisateur | P17: 3 – Mature
A18: =ROW()-3 -> 15 | B18: 46170 | C18: Qualité | D18: Alexandre | E18: Contrôle Qualité | F18: Socle de données | G18: Mezzoteam | H18: Gestion documentaires | I18: Externe | J18: MEZZOTEAM | K18: Manuel/Automatique | L18: Hebdomadaire | M18: Methode, Environnement, toutes les équipes mené à réalisé des documents | N18: Aucun | O18: Fluide | P18: Mature | Q18: Differentes partie prenantes, contrôle en interne de la conformité des doculents puis par la MOE qui emet ou pas un visa(refusé, commentaire, accepté) => pour les DAF (demande agrégation produit
A19: =ROW()-3 -> 16 | B19: 46170 | C19: Méthode/BIM | D19: Etienne | E19: GESTION DE MAQUETTES | F19: Socle de données | G19: Trimbleconnect | H19: Déposer les maquettes (sharepoint des maquettes) | I19: Externe | J19: tekla bimsight(licence) | K19: Manuel | L19: Tous les jours | M19: BE, Méthodes, | N19: Aucun | O19: Fluide | P19: Mature | Q19: 70 maquetttes généré par les bureau d'étude
A20: =ROW()-3 -> 17 | B20: 46170 | C20: Méthode/BIM | D20: Etienne | E20: PRODUCTION DE MAQUETTES | F20: Application métiers | G20: Revit | H20: Produire les maquettes(3D) | I20: Externe | J20: Autodesk(coût:système token) | K20: Manuel | L20: Tous les jours | M20: Méthode, BIM | N20: Aucun | O20: Fluide | P20: En developpement
B21: 46170 | C21: Méthode/BIM | D21: Etienne | E21: GESTION DE MAQUETTES | F21: Application métiers | G21: Sofistik bridge | H21: Modéliser la maquettes que pour le tunnel | I21: Externe | J21: Autodesk | K21: Manuel | L21: Ponctuel | M21: BIM | N21: Aucun | O21: Fluide
A22: =ROW()-3 -> 19 | B22: 46170 | C22: Méthode/BIM | D22: Etienne | E22: PRODUCTION DE MAQUETTES | F22: Application métiers | G22: Autocad | H22: Plan (production)=> 2D | I22: Externe | J22: Autodesk | K22: Manuel | L22: Tous les jours | M22: Méthode, BIM | N22: Aucun | O22: Fluide | P22: Mature
A23: =ROW()-3 -> 20 | B23: 46170 | C23: Méthode/BIM | D23: Etienne | E23: GESTION DE MAQUETTES | F23: Application métiers | G23: Inventor | H23: 3D => pièce mécanique | I23: Externe | J23: Autodesk | K23: Manuel | L23: Ponctuel | M23: Méthode, BIM | N23: Aucun | O23: Fluide | P23: Mature
A24: =ROW()-3 -> 21 | B24: 46170 | C24: Méthode/BIM | D24: Etienne | E24: PRODUCTION DE MAQUETTES | F24: Application métiers | G24: Civil 3D | H24: Dessein du terrassement | I24: Externe | J24: Autodesk | K24: Manuel | L24: Ponctuel | M24: Méthode, BIM | N24: Aucun | O24: Fluide | P24: Mature | Q24: Dépend du contexte et de l'objet à modéliser
A25: =ROW()-3 -> 22 | B25: 46170 | C25: Méthode/BIM | D25: Etienne | E25: GESTION DE MAQUETTES | F25: Application métiers | G25: Simple BIM | H25: Fusionnage de maquettes | I25: Externe | J25: Licence | K25: Manuel | L25: Hebdomadaire | M25: Etienne | N25: Aucun | O25: Fluide | P25: Mature
A26: =ROW()-3 -> 23 | B26: 46170 | C26: Méthode/BIM | D26: Etienne | E26: GESTION DE MAQUETTES | F26: Application métiers | G26: BIM vision | H26: Ouvrir une maquette | I26: Externe | J26: Technologia BIM | K26: Manuel | L26: Quotidien | M26: Lucas, Etienne, equipes travaux | N26: Aucun | O26: Fluide | P26: Mature
A27: =ROW()-3 -> 24 | B27: 46170 | C27: Méthode/BIM | D27: Etienne | E27: GESTION DE MAQUETTES | F27: Application métiers | G27: QGIS | H27: SIG, repère dans un plan | I27: Externe | J27: QGIS | K27: Manuel | L27: Ponctuel | M27: Topo, Directeur technique, pixis | N27: Aucun | O27: Pixis | P27: Mature
A28: =ROW()-3 -> 25 | B28: 46170 | C28: Méthode/BIM | D28: Etienne | E28: GESTION DE MAQUETTES | F28: Application métiers | G28: Anaconda | H28: Code | I28: Externe | K28: Manuel | L28: Ponctuel | M28: Etienne | N28: Aucun | P28: Mature
A29: =ROW()-3 -> 26 | B29: 46170 | C29: Méthode/BIM | D29: Etienne | E29: GESTION DE MAQUETTES | F29: Socle de données | G29: Mezzoteam | H29: Gestion documentaires | I29: Externe | J29: MEZZOTEAM | K29: Manuel/Automatique | L29: Hebdomadaire | M29: Methode, Environnement, toutes les équipes mené à réalisé des documents | N29: Aucun | O29: Fluide | P29: Mature | Q29: Differentes partie prenantes, contrôle en interne de la conformité des doculents puis par la MOE qui emet ou pas un visa(refusé, commentaire, accepté) => pour les DAF (demande agrégation produit
A30: =ROW()-3 -> 27 | B30: 46171 | C30: Contrat Manager | D30: Martin | E30: GESTION DES ENCAISSEMENTS | F30: Socle de données | G30: Excel | H30: Suivi des recettes et des montants cumulés , mesnuel => situation de travaux | I30: Externe | J30: Microsoft | K30: Manuel | L30: Tous les mois | M30: Tout le monde | N30: Aucun
A31: =ROW()-3 -> 28 | B31: 46171 | C31: Contrat Manager | D31: Martin | E31: GESTION DES ENCAISSEMENTS | F31: Application métiers | G31: E-project | H31: Permet d'activer la facturation , voir la situation | J31: Tisseo | K31: Manuel | L31: Ponctuel | N31: Martin | P31: En developpement
A32: =ROW()-3 -> 29 | B32: 46171 | C32: Contrat Manager | D32: Martin | E32: AVANCEMENTS JALON CHANTIER | F32: Application métiers | G32: Word | H32: Avancement avec les ingé | I32: Externe | J32: Microsoft | K32: Manuel | L32: Ponctuel | M32: Tout le monde | N32: Aucun
A33: =ROW()-3 -> 30 | B33: 46171 | C33: Contrat Manager | D33: Martin | E33: FACTURATION PARTENAIRE | F33: Application métiers | G33: Baseware | H33: Validé les facturations partenaires, | I33: Interne | J33: Soletanche | K33: Manuel | L33: Hebdomadaire | M33: Equipe de Gestion | N33: Harmonie | O33: Interne | P33: Mature
A34: =ROW()-3 -> 31 | B34: 46171 | C34: Contrat Manager | D34: Thierry | E34: GESTION DE CONTRATS | F34: Application métiers | G34: NotebookLM | H34: Redaction de document, mémoire, reclamation | I34: Interne | J34: GOOGLE | K34: Manuel | L34: Quotidien | M34: Thierry | N34: Aucun | P34: Mature
A35: =ROW()-3 -> 32 | B35: 46171 | C35: Contrat Manager | D35: Thierry | E35: GESTION DE CONTRATS | F35: Socle de données | G35: Sharepoint | H35: Accès aux documents | I35: Externe | J35: MICROSOFT | K35: Manuel | L35: Hebdomadaire | M35: Tous les services
A36: =ROW()-3 -> 33 | B36: 46171 | C36: Contrat Manager | D36: Thierry | E36: GESTION DE CONTRATS | F36: Socle de données | G36: Excel | I36: Externe | J36: MICROSOFT | K36: Manuel | L36: Hebdomadaire | M36: Tous les services | N36: Tous
A37: =ROW()-3 -> 34 | B37: 46171 | C37: Contrat Manager | D37: Thierry | E37: GESTION DE CONTRATS | F37: Application métiers | G37: Cabine de pilotage(Power BI) | H37: Suivi du pilotage/ avancement des chantiers | I37: Interne | J37: MICROSOFT | K37: Automatique | L37: Hebdomadaire | M37: Equipe travaux | O37: Excel | P37: Mature | Q37: (Power BI Miles stones management system )
A38: =ROW()-3 -> 35 | B38: 46190 | C38: Direction | D38: Morgan | E38: CIRCUIT DE VALIDATION | F38: Application métiers | G38: Baseware | H38: Validation | K38: Manuel
A39: =ROW()-3 -> 36 | B39: 46175 | C39: Comptabilité/gestion | D39: Abdellah | E39: ENGAGEMENT DES DÉPENSES | F39: Socle de données | G39: Harmony | H39: Engagements des dépenses à la reception des bl, suivre les commandes , envoi des avis de paiement, Pour les ST=> création d'un b.D.C=> basé sur la taille du contrat => situation mise à jour | I39: Interne | K39: Manuel | L39: Quotidien | M39: Pablo commande passé par les opérationneles trier par ateliers, Baseware | N39: Baseware | P39: Mature | Q39: Abdellah commence à engagé des dépenses par la reception des bl => une fois recpetionné transfert dans la PC100 => PAMS peut par la suite commencé le CB / Si litige => notation la différence de montant et enregistrement de la facture dans le PC100 => paiement du montant "légitime"=> discussion avec le fournisseur => génération d'un avoir ou paiement de la totalité
A40: =ROW()-3 -> 37 | B40: 46175 | C40: Comptabilité/gestion | D40: Abdellah | E40: GESTION DE FACTURATION | F40: Application métiers/Socle de donnée | G40: Excel | H40: Chronofacture, BDD factures, rapprochement entre la proposition d'ADF envoyé par SIHEM et les factures présents dans le BDD, envoie de la PC100 | I40: Interne | J40: Microsoft | K40: Manuel | L40: Tous les jours | M40: Équipe AGC | N40: Tout | P40: Mature
A41: =ROW()-3 -> 38 | B41: 46175 | C41: Comptabilité/gestion | D41: Abdellah | E41: GESTION DE FACTURATION | F41: Application métiers | G41: Docusign | H41: Notification d'un nouveau contrats | I41: Externe | K41: Automatique | L41: Hebdomadaire | M41: Membres d'une boucle de validation | N41: Tout
...

Sheet 📝 Guide Entretien
A1: GUIDE D'ENTRETIEN – CARTOGRAPHIE OUTILS IT CHANTIER
A2: 🔑 = Question prioritaire à ne pas manquer
A3: INTRODUCTION
A4: Présentation | B4: Bonjour, je suis [prénom], stagiaire CFI au sein de Bouygues Construction. Cartographie des outils IT utilisés sur le chantier afin d'en avoir une vision globale + interconnexions. | C4: Durée estimée : 30-45 min
A5: IDENTIFICATION
A6: Q1 | B6: 🔑 Quels outils / logiciels utilisez-vous au quotidien dans votre activité ? | C6: Lister tous les outils
A7: Q2 | B7: Depuis combien de temps utilisez-vous cet outil ? | C7: Date de mise en place
A8: USAGE
A9: Q3 | B9: 🔑 À quoi vous sert cet outil concrètement ? Quelle est son utilité principale ? | C9: Comprendre le cas d'usage métier
A10: Q4 | B10: Combien de personnes l'utilisent dans votre équipe / sur le chantier ? | C10: Volumétrie utilisateurs
A11: TECHNIQUE
A12: Q5 | B12: 🔑 Est-ce un outil développé en interne par Bouygues ou fourni par un éditeur externe ? | C12: Interne / Externe
A13: Q6 | B13: L'outil est-il hébergé en local ou dans le cloud ? | C13: Architecture technique
A14: ALIMENTATION DES DONNÉES
A15: Q7 | B15: 🔑 Comment les données sont-elles saisies dans l'outil ? Manuellement ou automatiquement ? | C15: Mode d'alimentation
A16: Q8 | B16: 🔑 Qui saisit / alimente les données ? Quel profil ? | C16: Responsable alimentation
A17: Q9 | B17: 🔑 À quelle fréquence les données sont-elles mises à jour ? | C17: Quotidien / hebdo / mensuel...
A18: INTERCONNEXIONS
A19: Q10 | B19: 🔑 Cet outil reçoit-il des données d'un autre outil ? Lequel ? | C19: Flux entrants
A20: Q11 | B20: 🔑 Cet outil envoie-t-il des données vers un autre outil ? Lequel ? | C20: Flux sortants
A21: Q12 | B21: Y a-t-il des exports réguliers (Excel, PDF, API...) ? Vers qui ? | C21: Format des échanges
A22: ÉVALUATION
A23: Q13 | B23: Êtes-vous satisfait de cet outil ? Quels sont ses points forts ? | C23: Satisfaction
A24: Q14 | B24: Quels sont les problèmes rencontrés ou les manques ? | C24: Points faibles / Risques
A25: Q15 | B25: Avez-vous des évolutions ou remplacements prévus ? | C25: Roadmap
A26: CLÔTURE
A27: Conclusion | B27: Y a-t-il d'autres outils que vous utilisez et que nous n'avons pas abordés ? Avez-vous des collègues à qui je devrais parler ? | C27: Identifier d'autres interlocuteurs

Sheet 📊 Tableau de Bord
A1: TABLEAU DE BORD – AVANCEMENT CARTOGRAPHIE
A3: Indicateur | B3: Valeur | C3: Source | H3: {=_xlfn.UNIQUE('📋 Collecte Entretiens'!D4:D93)} -> Julie | I3: {=_xlfn._xlws.SORT(_xlfn.UNIQUE('📋 Collecte Entretiens'!G4:G94,FALSE,FALSE))} -> Anaconda | J3: =INDEX('📋 Collecte Entretiens'!K4:K94,MATCH('📊 Tableau de Bord'!I3,'📋 Collecte Entretiens'!G4:G94,0)) -> Manuel
A4: Nb entretiens réalisés | B4: ='📋 Collecte Entretiens'!D103 -> 16 | C4: Feuille Collecte | H4: Alexandre | I4: Autocad
A5: Nb outils identifiés | B5: ='📋 Collecte Entretiens'!G103 -> 51 | C5: Feuille Collecte | H5: Alexandre | I5: Baseware
A6: Nb outils internes | B6: =COUNTIF('📋 Collecte Entretiens'!I4:I103,"Interne") -> 13 | C6: Feuille Collecte | H6: Etienne | I6: BATIS
A7: Nb outils externes | B7: =COUNTIF('📋 Collecte Entretiens'!I4:I103,"Externe") -> 47 | C7: Feuille Collecte | H7: Martin | I7: BIM vision
A8: Nb outils alimentation manuelle | B8: =COUNTIF('📋 Collecte Entretiens'!K4:K103,"Manuel") -> 84 | C8: Feuille Collecte | H8: Thierry | I8: BIP /BAPS
A9: Nb outils alimentation automatique | B9: =COUNTIF('📋 Collecte Entretiens'!K4:K103,"Automatique") -> 9 | C9: Feuille Collecte | H9: Thierry | I9: BY MY SITE
H10: Morgan | I10: Cabine de pilotage(Power BI)
H11: Abdellah | I11: Civil 3D
H12: Benjamin | I12: Covadis
H13: Sabine | I13: CWT
H14: Valerie | I14: Cyclone 3dr
H15: Laurie | I15: Docusign
H16: r | I16: E-checking
H17: Camille | I17: E-paraph
H18: Franck | I18: E-project
I19: ERP MAT
I20: Excel
I21: H&R For you
I22: Harmony
I23: IDCAPTURE
I24: Inventor
I25: La scene
I26: Lafarge +
I27: Liveobject(ORANGE)
I28: Lucee TP
I29: Mezzoteam
I30: MIRO
... I59: Achat +(achat pablo => opérationnel)
I60: Neoacces | J60: créer les badges => gère les accès

Sheet 🔍 Fiche Outil Détaillée
A1: FICHE DÉTAILLÉE – OUTIL IT
A2: IDENTIFICATION
A3: Nom de l'outil
A4: Éditeur / Fournisseur
A5: Version
A6: Site web / Documentation
A7: USAGE
A8: Fonction principale
A9: Service(s) utilisateur(s)
A10: Nombre d'utilisateurs
A11: Contexte d'utilisation
A12: TECHNIQUE
... A28: Commentaires libres
